Workbook

Sheet Project Brief
A1: Engineering Competency Gap Dashboard - Mock Dataset v2
A2: GE Vernova-style portfolio project: competency data, skill gap analysis, user support workflows, evidence control and leadership reporting.
A4: JD Alignment | B4: How this workbook supports the GE Vernova Data Analyst Intern - Competency Management role
A5: Competency models | B5: competency_model sheet simulates creating/modifying skill models, required levels and criticality.
A6: User/account support | B6: employees sheet includes account_status, people leader and role data to support user/account workflows.
A7: Data analysis | B7: assessments sheet uses formulas to calculate gap, severity, readiness, priority score and data quality flags.
A8: Evidence workflow | B8: evidence_log simulates uploaded assessment evidence, verification status, quality score and reviewer issues.
A9: Access audit | B9: access_audit simulates user permissions, access issues, ticket status and support ownership.
A10: Trend analysis | B10: assessment_history provides quarterly skill movement for readiness and gap trend reporting.
A11: Targets | B11: competency_targets gives team/area readiness targets for leadership comparison.
A12: Dashboards/reporting | B12: dashboard_seed sheet gives KPI and summary tables ready for Tableau or Power BI import.
A13: Leadership insight | B13: training_actions sheet links high-priority gaps to recommended training and ownership.
A14: Data accuracy | B14: Dataset intentionally includes stale assessments, missing evidence, inactive accounts and duplicate records.
A15: Next step | B15: Use Python/Pandas to clean the workbook, validate rules, export dashboard-ready data and create insight slides.
... A20: Target role | B20: Data Analyst Intern - Competency Management

Sheet employees
A1: employee_id | B1: employee_name | C1: team | D1: role_family | E1: job_level | F1: people_leader | G1: location | H1: account_status | I1: start_date
A2: E001 | B2: Avery Brown | C2: Asset Management | D2: Systems Engineering | E2: Senior Engineer | F2: Aisha Khan | G2: Stafford | H2: Active | I2: 45486.264
A3: E002 | B3: Alex Shah | C3: Systems Engineering | D3: Data & Reporting | E3: Engineer | F3: Sarah Williams | G3: Stafford | H3: Active | I3: 45915.75
A4: E003 | B4: Jamie Taylor | C4: Asset Management | D4: Systems Engineering | E4: Engineer | F4: Aisha Khan | G4: Stafford | H4: Active | I4: 44796.186
A5: E004 | B5: Riley Chen | C5: Protection & Control | D5: Engineering Management | E5: Engineer | F5: Aisha Khan | G5: Stafford | H5: Active | I5: 45478.276
A6: E005 | B6: Jamie Williams | C6: Systems Engineering | D6: Testing & Validation | E6: Senior Engineer | F6: Tom Evans | G6: Stafford | H6: Active | I6: 44900.813
A7: E006 | B7: Taylor Patel | C7: Protection & Control | D7: Software Engineering | E7: Senior Engineer | F7: Sarah Williams | G7: Stafford | H7: Active | I7: 45006.613
A8: E007 | B8: Morgan Nguyen | C8: Asset Management | D8: Data & Reporting | E8: Lead Engineer | F8: Tom Evans | G8: Stafford | H8: Active | I8: 45285.261
A9: E008 | B9: Morgan Williams | C9: HVDC | D9: Systems Engineering | E9: Engineer | F9: Mei Chen | G9: Stafford | H9: Active | I9: 44900.666
A10: E009 | B10: Riley Morgan | C10: Systems Engineering | D10: Testing & Validation | E10: Graduate | F10: Sarah Williams | G10: Stafford | H10: Active | I10: 44917.428
A11: E010 | B11: Jordan Khan | C11: HVDC | D11: Data & Reporting | E11: Senior Engineer | F11: James Walker | G11: Stafford | H11: Active | I11: 45883.026
A12: E011 | B12: Casey Walker | C12: Systems Engineering | D12: Software Engineering | E12: Graduate | F12: Priya Shah | G12: Stafford | H12: Active | I12: 45508.802
A13: E012 | B13: Morgan Khan | C13: Systems Engineering | D13: Testing & Validation | E13: Lead Engineer | F13: Priya Shah | G13: Stafford | H13: Active | I13: 45935.78
... A37: E036 | B37: Robin Patel | C37: Asset Management | D37: Testing & Validation | E37: Lead Engineer | F37: Tom Evans | G37: Stafford | H37: Active | I37: 45708.993

Sheet competency_model
A1: competency_id | B1: competency_model | C1: competency_area | D1: competency_name | E1: role_family | F1: required_level | G1: criticality
A2: C001 | B2: Grid Solutions Engineering | C2: Data Analysis | D2: Excel Data Cleaning | E2: Data & Reporting | F2: 4 | G2: High
A3: C002 | B3: Grid Solutions Engineering | C3: Data Analysis | D3: Python Data Cleaning | E3: Data & Reporting | F3: 4 | G3: High
A4: C003 | B4: Grid Solutions Engineering | C4: Data Analysis | D4: SQL Querying | E4: Data & Reporting | F4: 3 | G4: Medium
A5: C004 | B5: Grid Solutions Engineering | C5: Excel Reporting | D5: PivotTables and Power Query | E5: Data & Reporting | F5: 4 | G5: High
A6: C005 | B6: Grid Solutions Engineering | C6: Tableau | D6: Tableau Dashboard Building | E6: Data & Reporting | F6: 3 | G6: High
A7: C006 | B7: Grid Solutions Engineering | C7: PowerPoint Presentation | D7: Leadership Storytelling | E7: Data & Reporting | F7: 3 | G7: Medium
A8: C007 | B8: Grid Solutions Engineering | C8: Engineering Documentation | D8: Technical Documentation | E8: Systems Engineering | F8: 4 | G8: High
A9: C008 | B9: Grid Solutions Engineering | C9: Power Systems Knowledge | D9: Grid Protection Fundamentals | E9: Protection & Control | F9: 4 | G9: High
A10: C009 | B10: Grid Solutions Engineering | C10: Power Systems Knowledge | D10: HVDC System Concepts | E10: Systems Engineering | F10: 3 | G10: High
A11: C010 | B11: Grid Solutions Engineering | C11: Testing & Validation | D11: Test Evidence Review | E11: Testing & Validation | F11: 4 | G11: High
A12: C011 | B12: Grid Solutions Engineering | C12: Testing & Validation | D12: Defect Investigation | E12: Testing & Validation | F12: 3 | G12: Medium
A13: C012 | B13: Grid Solutions Engineering | C13: Safety / Compliance | D13: Engineering Safety Awareness | E13: Systems Engineering | F13: 4 | G13: High
... A25: C024 | B25: Grid Solutions Engineering | C25: Asset Management | D25: Engineering Performance Indicators | E25: Asset Management | F25: 3 | G25: High

Sheet assessments
A1: assessment_id | B1: employee_id | C1: employee_name | D1: team | E1: role_family | F1: job_level | G1: competency_id | H1: competency_area | I1: competency_name | J1: required_level | K1: criticality | L1: current_level | M1: gap | N1: gap_severity | O1: criticality_weight | P1: priority_score | Q1: readiness_status | R1: evidence_status | S1: assessment_date | T1: assessment_age_days | U1: assessor | V1: comments | W1: data_quality_flag
A2: A0001 | B2: E001 | C2: =IFERROR(INDEX(employees!$B$2:$B$37,MATCH(B2,employees!$A$2:$A$37,0)),"") -> Avery Brown | D2: =IFERROR(INDEX(employees!$C$2:$C$37,MATCH(B2,employees!$A$2:$A$37,0)),"") -> Asset Management | E2: =IFERROR(INDEX(employees!$D$2:$D$37,MATCH(B2,employees!$A$2:$A$37,0)),"") -> Systems Engineering | F2: =IFERROR(INDEX(employees!$E$2:$E$37,MATCH(B2,employees!$A$2:$A$37,0)),"") -> Senior Engineer | G2: C009 | H2: =IFERROR(INDEX(competency_model!$C$2:$C$25,MATCH(G2,competency_model!$A$2:$A$25,0)),"") -> Power Systems Knowledge | I2: =IFERROR(INDEX(competency_model!$D$2:$D$25,MATCH(G2,competency_model!$A$2:$A$25,0)),"") -> HVDC System Concepts | J2: =IFERROR(INDEX(competency_model!$F$2:$F$25,MATCH(G2,competency_model!$A$2:$A$25,0)),"") -> 3 | K2: =IFERROR(INDEX(competency_model!$G$2:$G$25,MATCH(G2,competency_model!$A$2:$A$25,0)),"") -> High | L2: 2 | M2: =MAX(0,J2-L2) -> 1 | N2: =IF(M2=0,"No Gap",IF(M2=1,"Minor",IF(M2=2,"Moderate","Critical"))) -> Minor | O2: =IF(K2="High",3,IF(K2="Medium",2,1)) -> 3 | P2: =M2*O2 -> 3 | Q2: =IF(L2>=J2,"Ready","Development Needed") -> Development Needed | R2: Missing | S2: 46181.326 | T2: =TODAY()-S2 -> 20.674453 | U2: Manager | W2: =IF(R2="Missing","Missing evidence",IF(T2>365,"Stale assessment",IF(COUNTIFS($B$2:$B$264,B2,$G$2:$G$264,G2)>1,"Duplicate competency record",IF(INDEX(employees!$H$2:$H$37,MATCH(B2,employees!$A$2:$A$37,0))="Inactive","Inactive account","OK")))) -> Missing evidence
A3: A0002 | B3: E001 | C3: =IFERROR(INDEX(employees!$B$2:$B$37,MATCH(B3,employees!$A$2:$A$37,0)),"") -> Avery Brown | D3: =IFERROR(INDEX(employees!$C$2:$C$37,MATCH(B3,employees!$A$2:$A$37,0)),"") -> Asset Management | E3: =IFERROR(INDEX(employees!$D$2:$D$37,MATCH(B3,employees!$A$2:$A$37,0)),"") -> Systems Engineering | F3: =IFERROR(INDEX(employees!$E$2:$E$37,MATCH(B3,employees!$A$2:$A$37,0)),"") -> Senior Engineer | G3: C020 | H3: =IFERROR(INDEX(competency_model!$C$2:$C$25,MATCH(G3,competency_model!$A$2:$A$25,0)),"") -> User Support | I3: =IFERROR(INDEX(competency_model!$D$2:$D$25,MATCH(G3,competency_model!$A$2:$A$25,0)),"") -> Competency Tool User Support | J3: =IFERROR(INDEX(competency_model!$F$2:$F$25,MATCH(G3,competency_model!$A$2:$A$25,0)),"") -> 3 | K3: =IFERROR(INDEX(competency_model!$G$2:$G$25,MATCH(G3,competency_model!$A$2:$A$25,0)),"") -> Medium | L3: 2 | M3: =MAX(0,J3-L3) -> 1 | N3: =IF(M3=0,"No Gap",IF(M3=1,"Minor",IF(M3=2,"Moderate","Critical"))) -> Minor | O3: =IF(K3="High",3,IF(K3="Medium",2,1)) -> 2 | P3: =M3*O3 -> 2 | Q3: =IF(L3>=J3,"Ready","Development Needed") -> Development Needed | R3: Partial | S3: 46190.881 | T3: =TODAY()-S3 -> 11.119105 | U3: Manager | V3: Ready for review | W3: =IF(R3="Missing","Missing evidence",IF(T3>365,"Stale assessment",IF(COUNTIFS($B$2:$B$264,B3,$G$2:$G$264,G3)>1,"Duplicate competency record",IF(INDEX(employees!$H$2:$H$37,MATCH(B3,employees!$A$2:$A$37,0))="Inactive","Inactive account","OK")))) -> OK
A4: A0003 | B4: E001 | C4: =IFERROR(INDEX(employees!$B$2:$B$37,MATCH(B4,employees!$A$2:$A$37,0)),"") -> Avery Brown | D4: =IFERROR(INDEX(employees!$C$2:$C$37,MATCH(B4,employees!$A$2:$A$37,0)),"") -> Asset Management | E4: =IFERROR(INDEX(employees!$D$2:$D$37,MATCH(B4,employees!$A$2:$A$37,0)),"") -> Systems Engineering | F4: =IFERROR(INDEX(employees!$E$2:$E$37,MATCH(B4,employees!$A$2:$A$37,0)),"") -> Senior Engineer | G4: C013 | H4: =IFERROR(INDEX(competency_model!$C$2:$C$25,MATCH(G4,competency_model!$A$2:$A$25,0)),"") -> Stakeholder Communication | I4: =IFERROR(INDEX(competency_model!$D$2:$D$25,MATCH(G4,competency_model!$A$2:$A$25,0)),"") -> Non-Technical Explanation | J4: =IFERROR(INDEX(competency_model!$F$2:$F$25,MATCH(G4,competency_model!$A$2:$A$25,0)),"") -> 3 | K4: =IFERROR(INDEX(competency_model!$G$2:$G$25,MATCH(G4,competency_model!$A$2:$A$25,0)),"") -> Medium | L4: 3 | M4: =MAX(0,J4-L4) -> 0 | N4: =IF(M4=0,"No Gap",IF(M4=1,"Minor",IF(M4=2,"Moderate","Critical"))) -> No Gap | O4: =IF(K4="High",3,IF(K4="Medium",2,1)) -> 2 | P4: =M4*O4 -> 0 | Q4: =IF(L4>=J4,"Ready","Development Needed") -> Ready | R4: Verified | S4: 45976.81 | T4: =TODAY()-S4 -> 225.18998 | U4: Self | W4: =IF(R4="Missing","Missing evidence",IF(T4>365,"Stale assessment",IF(COUNTIFS($B$2:$B$264,B4,$G$2:$G$264,G4)>1,"Duplicate competency record",IF(INDEX(employees!$H$2:$H$37,MATCH(B4,employees!$A$2:$A$37,0))="Inactive","Inactive account","OK")))) -> OK
A5: A0004 | B5: E001 | C5: =IFERROR(INDEX(employees!$B$2:$B$37,MATCH(B5,employees!$A$2:$A$37,0)),"") -> Avery Brown | D5: =IFERROR(INDEX(employees!$C$2:$C$37,MATCH(B5,employees!$A$2:$A$37,0)),"") -> Asset Management | E5: =IFERROR(INDEX(employees!$D$2:$D$37,MATCH(B5,employees!$A$2:$A$37,0)),"") -> Systems Engineering | F5: =IFERROR(INDEX(employees!$E$2:$E$37,MATCH(B5,employees!$A$2:$A$37,0)),"") -> Senior Engineer | G5: C004 | H5: =IFERROR(INDEX(competency_model!$C$2:$C$25,MATCH(G5,competency_model!$A$2:$A$25,0)),"") -> Excel Reporting | I5: =IFERROR(INDEX(competency_model!$D$2:$D$25,MATCH(G5,competency_model!$A$2:$A$25,0)),"") -> PivotTables and Power Query | J5: =IFERROR(INDEX(competency_model!$F$2:$F$25,MATCH(G5,competency_model!$A$2:$A$25,0)),"") -> 4 | K5: =IFERROR(INDEX(competency_model!$G$2:$G$25,MATCH(G5,competency_model!$A$2:$A$25,0)),"") -> High | L5: 1 | M5: =MAX(0,J5-L5) -> 3 | N5: =IF(M5=0,"No Gap",IF(M5=1,"Minor",IF(M5=2,"Moderate","Critical"))) -> Critical | O5: =IF(K5="High",3,IF(K5="Medium",2,1)) -> 3 | P5: =M5*O5 -> 9 | Q5: =IF(L5>=J5,"Ready","Development Needed") -> Development Needed | R5: Partial | S5: 46094.424 | T5: =TODAY()-S5 -> 107.57561 | U5: Manager | V5: Needs evidence upload | W5: =IF(R5="Missing","Missing evidence",IF(T5>365,"Stale assessment",IF(COUNTIFS($B$2:$B$264,B5,$G$2:$G$264,G5)>1,"Duplicate competency record",IF(INDEX(employees!$H$2:$H$37,MATCH(B5,employees!$A$2:$A$37,0))="Inactive","Inactive account","OK")))) -> OK
A6: A0005 | B6: E001 | C6: =IFERROR(INDEX(employees!$B$2:$B$37,MATCH(B6,employees!$A$2:$A$37,0)),"") -> Avery Brown | D6: =IFERROR(INDEX(employees!$C$2:$C$37,MATCH(B6,employees!$A$2:$A$37,0)),"") -> Asset Management | E6: =IFERROR(INDEX(employees!$D$2:$D$37,MATCH(B6,employees!$A$2:$A$37,0)),"") -> Systems Engineering | F6: =IFERROR(INDEX(employees!$E$2:$E$37,MATCH(B6,employees!$A$2:$A$37,0)),"") -> Senior Engineer | G6: C006 | H6: =IFERROR(INDEX(competency_model!$C$2:$C$25,MATCH(G6,competency_model!$A$2:$A$25,0)),"") -> PowerPoint Presentation | I6: =IFERROR(INDEX(competency_model!$D$2:$D$25,MATCH(G6,competency_model!$A$2:$A$25,0)),"") -> Leadership Storytelling | J6: =IFERROR(INDEX(competency_model!$F$2:$F$25,MATCH(G6,competency_model!$A$2:$A$25,0)),"") -> 3 | K6: =IFERROR(INDEX(competency_model!$G$2:$G$25,MATCH(G6,competency_model!$A$2:$A$25,0)),"") -> Medium | L6: 2 | M6: =MAX(0,J6-L6) -> 1 | N6: =IF(M6=0,"No Gap",IF(M6=1,"Minor",IF(M6=2,"Moderate","Critical"))) -> Minor | O6: =IF(K6="High",3,IF(K6="Medium",2,1)) -> 2 | P6: =M6*O6 -> 2 | Q6: =IF(L6>=J6,"Ready","Development Needed") -> Development Needed | R6: Verified | S6: 46162.996 | T6: =TODAY()-S6 -> 39.004066 | U6: Self | V6: Discuss training route with leader | W6: =IF(R6="Missing","Missing evidence",IF(T6>365,"Stale assessment",IF(COUNTIFS($B$2:$B$264,B6,$G$2:$G$264,G6)>1,"Duplicate competency record",IF(INDEX(employees!$H$2:$H$37,MATCH(B6,employees!$A$2:$A$37,0))="Inactive","Inactive account","OK")))) -> OK
A7: A0006 | B7: E001 | C7: =IFERROR(INDEX(employees!$B$2:$B$37,MATCH(B7,employees!$A$2:$A$37,0)),"") -> Avery Brown | D7: =IFERROR(INDEX(employees!$C$2:$C$37,MATCH(B7,employees!$A$2:$A$37,0)),"") -> Asset Management | E7: =IFERROR(INDEX(employees!$D$2:$D$37,MATCH(B7,employees!$A$2:$A$37,0)),"") -> Systems Engineering | F7: =IFERROR(INDEX(employees!$E$2:$E$37,MATCH(B7,employees!$A$2:$A$37,0)),"") -> Senior Engineer | G7: C024 | H7: =IFERROR(INDEX(competency_model!$C$2:$C$25,MATCH(G7,competency_model!$A$2:$A$25,0)),"") -> Asset Management | I7: =IFERROR(INDEX(competency_model!$D$2:$D$25,MATCH(G7,competency_model!$A$2:$A$25,0)),"") -> Engineering Performance Indicators | J7: =IFERROR(INDEX(competency_model!$F$2:$F$25,MATCH(G7,competency_model!$A$2:$A$25,0)),"") -> 3 | K7: =IFERROR(INDEX(competency_model!$G$2:$G$25,MATCH(G7,competency_model!$A$2:$A$25,0)),"") -> High | L7: 1 | M7: =MAX(0,J7-L7) -> 2 | N7: =IF(M7=0,"No Gap",IF(M7=1,"Minor",IF(M7=2,"Moderate","Critical"))) -> Moderate | O7: =IF(K7="High",3,IF(K7="Medium",2,1)) -> 3 | P7: =M7*O7 -> 6 | Q7: =IF(L7>=J7,"Ready","Development Needed") -> Development Needed | R7: Missing | S7: 46131.1 | T7: =TODAY()-S7 -> 70.900424 | U7: Manager | W7: =IF(R7="Missing","Missing evidence",IF(T7>365,"Stale assessment",IF(COUNTIFS($B$2:$B$264,B7,$G$2:$G$264,G7)>1,"Duplicate competency record",IF(INDEX(employees!$H$2:$H$37,MATCH(B7,employees!$A$2:$A$37,0))="Inactive","Inactive account","OK")))) -> Missing evidence
A8: A0007 | B8: E001 | C8: =IFERROR(INDEX(employees!$B$2:$B$37,MATCH(B8,employees!$A$2:$A$37,0)),"") -> Avery Brown | D8: =IFERROR(INDEX(employees!$C$2:$C$37,MATCH(B8,employees!$A$2:$A$37,0)),"") -> Asset Management | E8: =IFERROR(INDEX(employees!$D$2:$D$37,MATCH(B8,employees!$A$2:$A$37,0)),"") -> Systems Engineering | F8: =IFERROR(INDEX(employees!$E$2:$E$37,MATCH(B8,employees!$A$2:$A$37,0)),"") -> Senior Engineer | G8: C014 | H8: =IFERROR(INDEX(competency_model!$C$2:$C$25,MATCH(G8,competency_model!$A$2:$A$25,0)),"") -> Stakeholder Communication | I8: =IFERROR(INDEX(competency_model!$D$2:$D$25,MATCH(G8,competency_model!$A$2:$A$25,0)),"") -> Cross-Functional Updates | J8: =IFERROR(INDEX(competency_model!$F$2:$F$25,MATCH(G8,competency_model!$A$2:$A$25,0)),"") -> 3 | K8: =IFERROR(INDEX(competency_model!$G$2:$G$25,MATCH(G8,competency_model!$A$2:$A$25,0)),"") -> Medium | L8: 1 | M8: =MAX(0,J8-L8) -> 2 | N8: =IF(M8=0,"No Gap",IF(M8=1,"Minor",IF(M8=2,"Moderate","Critical"))) -> Moderate | O8: =IF(K8="High",3,IF(K8="Medium",2,1)) -> 2 | P8: =M8*O8 -> 4 | Q8: =IF(L8>=J8,"Ready","Development Needed") -> Development Needed | R8: Missing | S8: 46098.836 | T8: =TODAY()-S8 -> 103.16445 | U8: Self | W8: =IF(R8="Missing","Missing evidence",IF(T8>365,"Stale assessment",IF(COUNTIFS($B$2:$B$264,B8,$G$2:$G$264,G8)>1,"Duplicate competency record",IF(INDEX(employees!$H$2:$H$37,MATCH(B8,employees!$A$2:$A$37,0))="Inactive","Inactive account","OK")))) -> Missing evidence
A9: A0008 | B9: E001 | C9: =IFERROR(INDEX(employees!$B$2:$B$37,MATCH(B9,employees!$A$2:$A$37,0)),"") -> Avery Brown | D9: =IFERROR(INDEX(employees!$C$2:$C$37,MATCH(B9,employees!$A$2:$A$37,0)),"") -> Asset Management | E9: =IFERROR(INDEX(employees!$D$2:$D$37,MATCH(B9,employees!$A$2:$A$37,0)),"") -> Systems Engineering | F9: =IFERROR(INDEX(employees!$E$2:$E$37,MATCH(B9,employees!$A$2:$A$37,0)),"") -> Senior Engineer | G9: C007 | H9: =IFERROR(INDEX(competency_model!$C$2:$C$25,MATCH(G9,competency_model!$A$2:$A$25,0)),"") -> Engineering Documentation | I9: =IFERROR(INDEX(competency_model!$D$2:$D$25,MATCH(G9,competency_model!$A$2:$A$25,0)),"") -> Technical Documentation | J9: =IFERROR(INDEX(competency_model!$F$2:$F$25,MATCH(G9,competency_model!$A$2:$A$25,0)),"") -> 4 | K9: =IFERROR(INDEX(competency_model!$G$2:$G$25,MATCH(G9,competency_model!$A$2:$A$25,0)),"") -> High | L9: 3 | M9: =MAX(0,J9-L9) -> 1 | N9: =IF(M9=0,"No Gap",IF(M9=1,"Minor",IF(M9=2,"Moderate","Critical"))) -> Minor | O9: =IF(K9="High",3,IF(K9="Medium",2,1)) -> 3 | P9: =M9*O9 -> 3 | Q9: =IF(L9>=J9,"Ready","Development Needed") -> Development Needed | R9: Verified | S9: 45967.587 | T9: =TODAY()-S9 -> 234.41336 | U9: Self | W9: =IF(R9="Missing","Missing evidence",IF(T9>365,"Stale assessment",IF(COUNTIFS($B$2:$B$264,B9,$G$2:$G$264,G9)>1,"Duplicate competency record",IF(INDEX(employees!$H$2:$H$37,MATCH(B9,employees!$A$2:$A$37,0))="Inactive","Inactive account","OK")))) -> OK
A10: A0009 | B10: E002 | C10: =IFERROR(INDEX(employees!$B$2:$B$37,MATCH(B10,employees!$A$2:$A$37,0)),"") -> Alex Shah | D10: =IFERROR(INDEX(employees!$C$2:$C$37,MATCH(B10,employees!$A$2:$A$37,0)),"") -> Systems Engineering | E10: =IFERROR(INDEX(employees!$D$2:$D$37,MATCH(B10,employees!$A$2:$A$37,0)),"") -> Data & Reporting | F10: =IFERROR(INDEX(employees!$E$2:$E$37,MATCH(B10,employees!$A$2:$A$37,0)),"") -> Engineer | G10: C020 | H10: =IFERROR(INDEX(competency_model!$C$2:$C$25,MATCH(G10,competency_model!$A$2:$A$25,0)),"") -> User Support | I10: =IFERROR(INDEX(competency_model!$D$2:$D$25,MATCH(G10,competency_model!$A$2:$A$25,0)),"") -> Competency Tool User Support | J10: =IFERROR(INDEX(competency_model!$F$2:$F$25,MATCH(G10,competency_model!$A$2:$A$25,0)),"") -> 3 | K10: =IFERROR(INDEX(competency_model!$G$2:$G$25,MATCH(G10,competency_model!$A$2:$A$25,0)),"") -> Medium | L10: 1 | M10: =MAX(0,J10-L10) -> 2 | N10: =IF(M10=0,"No Gap",IF(M10=1,"Minor",IF(M10=2,"Moderate","Critical"))) -> Moderate | O10: =IF(K10="High",3,IF(K10="Medium",2,1)) -> 2 | P10: =M10*O10 -> 4 | Q10: =IF(L10>=J10,"Ready","Development Needed") -> Development Needed | R10: Verified | S10: 46160.616 | T10: =TODAY()-S10 -> 41.384007 | U10: Self | V10: Ready for review | W10: =IF(R10="Missing","Missing evidence",IF(T10>365,"Stale assessment",IF(COUNTIFS($B$2:$B$264,B10,$G$2:$G$264,G10)>1,"Duplicate competency record",IF(INDEX(employees!$H$2:$H$37,MATCH(B10,employees!$A$2:$A$37,0))="Inactive","Inactive account","OK")))) -> OK
A11: A0010 | B11: E002 | C11: =IFERROR(INDEX(employees!$B$2:$B$37,MATCH(B11,employees!$A$2:$A$37,0)),"") -> Alex Shah | D11: =IFERROR(INDEX(employees!$C$2:$C$37,MATCH(B11,employees!$A$2:$A$37,0)),"") -> Systems Engineering | E11: =IFERROR(INDEX(employees!$D$2:$D$37,MATCH(B11,employees!$A$2:$A$37,0)),"") -> Data & Reporting | F11: =IFERROR(INDEX(employees!$E$2:$E$37,MATCH(B11,employees!$A$2:$A$37,0)),"") -> Engineer | G11: C002 | H11: =IFERROR(INDEX(competency_model!$C$2:$C$25,MATCH(G11,competency_model!$A$2:$A$25,0)),"") -> Data Analysis | I11: =IFERROR(INDEX(competency_model!$D$2:$D$25,MATCH(G11,competency_model!$A$2:$A$25,0)),"") -> Python Data Cleaning | J11: =IFERROR(INDEX(competency_model!$F$2:$F$25,MATCH(G11,competency_model!$A$2:$A$25,0)),"") -> 4 | K11: =IFERROR(INDEX(competency_model!$G$2:$G$25,MATCH(G11,competency_model!$A$2:$A$25,0)),"") -> High | L11: 2 | M11: =MAX(0,J11-L11) -> 2 | N11: =IF(M11=0,"No Gap",IF(M11=1,"Minor",IF(M11=2,"Moderate","Critical"))) -> Moderate | O11: =IF(K11="High",3,IF(K11="Medium",2,1)) -> 3 | P11: =M11*O11 -> 6 | Q11: =IF(L11>=J11,"Ready","Development Needed") -> Development Needed | R11: Partial | S11: 46057.997 | T11: =TODAY()-S11 -> 144.0028 | U11: Self | V11: Needs practical project evidence | W11: =IF(R11="Missing","Missing evidence",IF(T11>365,"Stale assessment",IF(COUNTIFS($B$2:$B$264,B11,$G$2:$G$264,G11)>1,"Duplicate competency record",IF(INDEX(employees!$H$2:$H$37,MATCH(B11,employees!$A$2:$A$37,0))="Inactive","Inactive account","OK")))) -> OK
A12: A0011 | B12: E002 | C12: =IFERROR(INDEX(employees!$B$2:$B$37,MATCH(B12,employees!$A$2:$A$37,0)),"") -> Alex Shah | D12: =IFERROR(INDEX(employees!$C$2:$C$37,MATCH(B12,employees!$A$2:$A$37,0)),"") -> Systems Engineering | E12: =IFERROR(INDEX(employees!$D$2:$D$37,MATCH(B12,employees!$A$2:$A$37,0)),"") -> Data & Reporting | F12: =IFERROR(INDEX(employees!$E$2:$E$37,MATCH(B12,employees!$A$2:$A$37,0)),"") -> Engineer | G12: C017 | H12: =IFERROR(INDEX(competency_model!$C$2:$C$25,MATCH(G12,competency_model!$A$2:$A$25,0)),"") -> Data Quality | I12: =IFERROR(INDEX(competency_model!$D$2:$D$25,MATCH(G12,competency_model!$A$2:$A$25,0)),"") -> Duplicate and Missing Value Checks | J12: =IFERROR(INDEX(competency_model!$F$2:$F$25,MATCH(G12,competency_model!$A$2:$A$25,0)),"") -> 4 | K12: =IFERROR(INDEX(competency_model!$G$2:$G$25,MATCH(G12,competency_model!$A$2:$A$25,0)),"") -> High | L12: 2 | M12: =MAX(0,J12-L12) -> 2 | N12: =IF(M12=0,"No Gap",IF(M12=1,"Minor",IF(M12=2,"Moderate","Critical"))) -> Moderate | O12: =IF(K12="High",3,IF(K12="Medium",2,1)) -> 3 | P12: =M12*O12 -> 6 | Q12: =IF(L12>=J12,"Ready","Development Needed") -> Development Needed | R12: Verified | S12: 45817.479 | T12: =TODAY()-S12 -> 384.52089 | U12: Manager | W12: =IF(R12="Missing","Missing evidence",IF(T12>365,"Stale assessment",IF(COUNTIFS($B$2:$B$264,B12,$G$2:$G$264,G12)>1,"Duplicate competency record",IF(INDEX(employees!$H$2:$H$37,MATCH(B12,employees!$A$2:$A$37,0))="Inactive","Inactive account","OK")))) -> Stale assessment
A13: A0012 | B13: E002 | C13: =IFERROR(INDEX(employees!$B$2:$B$37,MATCH(B13,employees!$A$2:$A$37,0)),"") -> Alex Shah | D13: =IFERROR(INDEX(employees!$C$2:$C$37,MATCH(B13,employees!$A$2:$A$37,0)),"") -> Systems Engineering | E13: =IFERROR(INDEX(employees!$D$2:$D$37,MATCH(B13,employees!$A$2:$A$37,0)),"") -> Data & Reporting | F13: =IFERROR(INDEX(employees!$E$2:$E$37,MATCH(B13,employees!$A$2:$A$37,0)),"") -> Engineer | G13: C003 | H13: =IFERROR(INDEX(competency_model!$C$2:$C$25,MATCH(G13,competency_model!$A$2:$A$25,0)),"") -> Data Analysis | I13: =IFERROR(INDEX(competency_model!$D$2:$D$25,MATCH(G13,competency_model!$A$2:$A$25,0)),"") -> SQL Querying | J13: =IFERROR(INDEX(competency_model!$F$2:$F$25,MATCH(G13,competency_model!$A$2:$A$25,0)),"") -> 3 | K13: =IFERROR(INDEX(competency_model!$G$2:$G$25,MATCH(G13,competency_model!$A$2:$A$25,0)),"") -> Medium | L13: 1 | M13: =MAX(0,J13-L13) -> 2 | N13: =IF(M13=0,"No Gap",IF(M13=1,"Minor",IF(M13=2,"Moderate","Critical"))) -> Moderate | O13: =IF(K13="High",3,IF(K13="Medium",2,1)) -> 2 | P13: =M13*O13 -> 4 | Q13: =IF(L13>=J13,"Ready","Development Needed") -> Development Needed | R13: Verified | S13: 46012.563 | T13: =TODAY()-S13 -> 189.43654 | U13: System | W13: =IF(R13="Missing","Missing evidence",IF(T13>365,"Stale assessment",IF(COUNTIFS($B$2:$B$264,B13,$G$2:$G$264,G13)>1,"Duplicate competency record",IF(INDEX(employees!$H$2:$H$37,MATCH(B13,employees!$A$2:$A$37,0))="Inactive","Inactive account","OK")))) -> OK
A14: A0013 | B14: E002 | C14: =IFERROR(INDEX(employees!$B$2:$B$37,MATCH(B14,employees!$A$2:$A$37,0)),"") -> Alex Shah | D14: =IFERROR(INDEX(employees!$C$2:$C$37,MATCH(B14,employees!$A$2:$A$37,0)),"") -> Systems Engineering | E14: =IFERROR(INDEX(employees!$D$2:$D$37,MATCH(B14,employees!$A$2:$A$37,0)),"") -> Data & Reporting | F14: =IFERROR(INDEX(employees!$E$2:$E$37,MATCH(B14,employees!$A$2:$A$37,0)),"") -> Engineer | G14: C006 | H14: =IFERROR(INDEX(competency_model!$C$2:$C$25,MATCH(G14,competency_model!$A$2:$A$25,0)),"") -> PowerPoint Presentation | I14: =IFERROR(INDEX(competency_model!$D$2:$D$25,MATCH(G14,competency_model!$A$2:$A$25,0)),"") -> Leadership Storytelling | J14: =IFERROR(INDEX(competency_model!$F$2:$F$25,MATCH(G14,competency_model!$A$2:$A$25,0)),"") -> 3 | K14: =IFERROR(INDEX(competency_model!$G$2:$G$25,MATCH(G14,competency_model!$A$2:$A$25,0)),"") -> Medium | L14: 3 | M14: =MAX(0,J14-L14) -> 0 | N14: =IF(M14=0,"No Gap",IF(M14=1,"Minor",IF(M14=2,"Moderate","Critical"))) -> No Gap | O14: =IF(K14="High",3,IF(K14="Medium",2,1)) -> 2 | P14: =M14*O14 -> 0 | Q14: =IF(L14>=J14,"Ready","Development Needed") -> Ready | R14: Missing | S14: 46005.538 | T14: =TODAY()-S14 -> 196.46162 | U14: Manager | W14: =IF(R14="Missing","Missing evidence",IF(T14>365,"Stale assessment",IF(COUNTIFS($B$2:$B$264,B14,$G$2:$G$264,G14)>1,"Duplicate competency record",IF(INDEX(employees!$H$2:$H$37,MATCH(B14,employees!$A$2:$A$37,0))="Inactive","Inactive account","OK")))) -> Missing evidence
A15: A0014 | B15: E002 | C15: =IFERROR(INDEX(employees!$B$2:$B$37,MATCH(B15,employees!$A$2:$A$37,0)),"") -> Alex Shah | D15: =IFERROR(INDEX(employees!$C$2:$C$37,MATCH(B15,employees!$A$2:$A$37,0)),"") -> Systems Engineering | E15: =IFERROR(INDEX(employees!$D$2:$D$37,MATCH(B15,employees!$A$2:$A$37,0)),"") -> Data & Reporting | F15: =IFERROR(INDEX(employees!$E$2:$E$37,MATCH(B15,employees!$A$2:$A$37,0)),"") -> Engineer | G15: C022 | H15: =IFERROR(INDEX(competency_model!$C$2:$C$25,MATCH(G15,competency_model!$A$2:$A$25,0)),"") -> Tableau | I15: =IFERROR(INDEX(competency_model!$D$2:$D$25,MATCH(G15,competency_model!$A$2:$A$25,0)),"") -> Dashboard Filtering and Actions | J15: =IFERROR(INDEX(competency_model!$F$2:$F$25,MATCH(G15,competency_model!$A$2:$A$25,0)),"") -> 3 | K15: =IFERROR(INDEX(competency_model!$G$2:$G$25,MATCH(G15,competency_model!$A$2:$A$25,0)),"") -> Medium | L15: 3 | M15: =MAX(0,J15-L15) -> 0 | N15: =IF(M15=0,"No Gap",IF(M15=1,"Minor",IF(M15=2,"Moderate","Critical"))) -> No Gap | O15: =IF(K15="High",3,IF(K15="Medium",2,1)) -> 2 | P15: =M15*O15 -> 0 | Q15: =IF(L15>=J15,"Ready","Development Needed") -> Ready | R15: Missing | S15: 46134.595 | T15: =TODAY()-S15 -> 67.404606 | U15: System | W15: =IF(R15="Missing","Missing evidence",IF(T15>365,"Stale assessment",IF(COUNTIFS($B$2:$B$264,B15,$G$2:$G$264,G15)>1,"Duplicate competency record",IF(INDEX(employees!$H$2:$H$37,MATCH(B15,employees!$A$2:$A$37,0))="Inactive","Inactive account","OK")))) -> Missing evidence
A16: A0015 | B16: E002 | C16: =IFERROR(INDEX(employees!$B$2:$B$37,MATCH(B16,employees!$A$2:$A$37,0)),"") -> Alex Shah | D16: =IFERROR(INDEX(employees!$C$2:$C$37,MATCH(B16,employees!$A$2:$A$37,0)),"") -> Systems Engineering | E16: =IFERROR(INDEX(employees!$D$2:$D$37,MATCH(B16,employees!$A$2:$A$37,0)),"") -> Data & Reporting | F16: =IFERROR(INDEX(employees!$E$2:$E$37,MATCH(B16,employees!$A$2:$A$37,0)),"") -> Engineer | G16: C005 | H16: =IFERROR(INDEX(competency_model!$C$2:$C$25,MATCH(G16,competency_model!$A$2:$A$25,0)),"") -> Tableau | I16: =IFERROR(INDEX(competency_model!$D$2:$D$25,MATCH(G16,competency_model!$A$2:$A$25,0)),"") -> Tableau Dashboard Building | J16: =IFERROR(INDEX(competency_model!$F$2:$F$25,MATCH(G16,competency_model!$A$2:$A$25,0)),"") -> 3 | K16: =IFERROR(INDEX(competency_model!$G$2:$G$25,MATCH(G16,competency_model!$A$2:$A$25,0)),"") -> High | L16: 2 | M16: =MAX(0,J16-L16) -> 1 | N16: =IF(M16=0,"No Gap",IF(M16=1,"Minor",IF(M16=2,"Moderate","Critical"))) -> Minor | O16: =IF(K16="High",3,IF(K16="Medium",2,1)) -> 3 | P16: =M16*O16 -> 3 | Q16: =IF(L16>=J16,"Ready","Development Needed") -> Development Needed | R16: Verified | S16: 45988.594 | T16: =TODAY()-S16 -> 213.40571 | U16: System | V16: Ready for review | W16: =IF(R16="Missing","Missing evidence",IF(T16>365,"Stale assessment",IF(COUNTIFS($B$2:$B$264,B16,$G$2:$G$264,G16)>1,"Duplicate competency record",IF(INDEX(employees!$H$2:$H$37,MATCH(B16,employees!$A$2:$A$37,0))="Inactive","Inactive account","OK")))) -> OK
A17: A0016 | B17: E002 | C17: =IFERROR(INDEX(employees!$B$2:$B$37,MATCH(B17,employees!$A$2:$A$37,0)),"") -> Alex Shah | D17: =IFERROR(INDEX(employees!$C$2:$C$37,MATCH(B17,employees!$A$2:$A$37,0)),"") -> Systems Engineering | E17: =IFERROR(INDEX(employees!$D$2:$D$37,MATCH(B17,employees!$A$2:$A$37,0)),"") -> Data & Reporting | F17: =IFERROR(INDEX(employees!$E$2:$E$37,MATCH(B17,employees!$A$2:$A$37,0)),"") -> Engineer | G17: C001 | H17: =IFERROR(INDEX(competency_model!$C$2:$C$25,MATCH(G17,competency_model!$A$2:$A$25,0)),"") -> Data Analysis | I17: =IFERROR(INDEX(competency_model!$D$2:$D$25,MATCH(G17,competency_model!$A$2:$A$25,0)),"") -> Excel Data Cleaning | J17: =IFERROR(INDEX(competency_model!$F$2:$F$25,MATCH(G17,competency_model!$A$2:$A$25,0)),"") -> 4 | K17: =IFERROR(INDEX(competency_model!$G$2:$G$25,MATCH(G17,competency_model!$A$2:$A$25,0)),"") -> High | L17: 2 | M17: =MAX(0,J17-L17) -> 2 | N17: =IF(M17=0,"No Gap",IF(M17=1,"Minor",IF(M17=2,"Moderate","Critical"))) -> Moderate | O17: =IF(K17="High",3,IF(K17="Medium",2,1)) -> 3 | P17: =M17*O17 -> 6 | Q17: =IF(L17>=J17,"Ready","Development Needed") -> Development Needed | R17: Verified | S17: 46103.955 | T17: =TODAY()-S17 -> 98.045204 | U17: Manager | W17: =IF(R17="Missing","Missing evidence",IF(T17>365,"Stale assessment",IF(COUNTIFS($B$2:$B$264,B17,$G$2:$G$264,G17)>1,"Duplicate competency record",IF(INDEX(employees!$H$2:$H$37,MATCH(B17,employees!$A$2:$A$37,0))="Inactive","Inactive account","OK")))) -> OK
A18: A0017 | B18: E003 | C18: =IFERROR(INDEX(employees!$B$2:$B$37,MATCH(B18,employees!$A$2:$A$37,0)),"") -> Jamie Taylor | D18: =IFERROR(INDEX(employees!$C$2:$C$37,MATCH(B18,employees!$A$2:$A$37,0)),"") -> Asset Management | E18: =IFERROR(INDEX(employees!$D$2:$D$37,MATCH(B18,employees!$A$2:$A$37,0)),"") -> Systems Engineering | F18: =IFERROR(INDEX(employees!$E$2:$E$37,MATCH(B18,employees!$A$2:$A$37,0)),"") -> Engineer | G18: C012 | H18: =IFERROR(INDEX(competency_model!$C$2:$C$25,MATCH(G18,competency_model!$A$2:$A$25,0)),"") -> Safety / Compliance | I18: =IFERROR(INDEX(competency_model!$D$2:$D$25,MATCH(G18,competency_model!$A$2:$A$25,0)),"") -> Engineering Safety Awareness | J18: =IFERROR(INDEX(competency_model!$F$2:$F$25,MATCH(G18,competency_model!$A$2:$A$25,0)),"") -> 4 | K18: =IFERROR(INDEX(competency_model!$G$2:$G$25,MATCH(G18,competency_model!$A$2:$A$25,0)),"") -> High | L18: 4 | M18: =MAX(0,J18-L18) -> 0 | N18: =IF(M18=0,"No Gap",IF(M18=1,"Minor",IF(M18=2,"Moderate","Critical"))) -> No Gap | O18: =IF(K18="High",3,IF(K18="Medium",2,1)) -> 3 | P18: =M18*O18 -> 0 | Q18: =IF(L18>=J18,"Ready","Development Needed") -> Ready | R18: Verified | S18: 45764.867 | T18: =TODAY()-S18 -> 437.13319 | U18: Manager | W18: =IF(R18="Missing","Missing evidence",IF(T18>365,"Stale assessment",IF(COUNTIFS($B$2:$B$264,B18,$G$2:$G$264,G18)>1,"Duplicate competency record",IF(INDEX(employees!$H$2:$H$37,MATCH(B18,employees!$A$2:$A$37,0))="Inactive","Inactive account","OK")))) -> Stale assessment
A19: A0018 | B19: E003 | C19: =IFERROR(INDEX(employees!$B$2:$B$37,MATCH(B19,employees!$A$2:$A$37,0)),"") -> Jamie Taylor | D19: =IFERROR(INDEX(employees!$C$2:$C$37,MATCH(B19,employees!$A$2:$A$37,0)),"") -> Asset Management | E19: =IFERROR(INDEX(employees!$D$2:$D$37,MATCH(B19,employees!$A$2:$A$37,0)),"") -> Systems Engineering | F19: =IFERROR(INDEX(employees!$E$2:$E$37,MATCH(B19,employees!$A$2:$A$37,0)),"") -> Engineer | G19: C007 | H19: =IFERROR(INDEX(competency_model!$C$2:$C$25,MATCH(G19,competency_model!$A$2:$A$25,0)),"") -> Engineering Documentation | I19: =IFERROR(INDEX(competency_model!$D$2:$D$25,MATCH(G19,competency_model!$A$2:$A$25,0)),"") -> Technical Documentation | J19: =IFERROR(INDEX(competency_model!$F$2:$F$25,MATCH(G19,competency_model!$A$2:$A$25,0)),"") -> 4 | K19: =IFERROR(INDEX(competency_model!$G$2:$G$25,MATCH(G19,competency_model!$A$2:$A$25,0)),"") -> High | L19: 4 | M19: =MAX(0,J19-L19) -> 0 | N19: =IF(M19=0,"No Gap",IF(M19=1,"Minor",IF(M19=2,"Moderate","Critical"))) -> No Gap | O19: =IF(K19="High",3,IF(K19="Medium",2,1)) -> 3 | P19: =M19*O19 -> 0 | Q19: =IF(L19>=J19,"Ready","Development Needed") -> Ready | R19: Missing | S19: 45974.816 | T19: =TODAY()-S19 -> 227.18406 | U19: Manager | V19: Needs evidence upload | W19: =IF(R19="Missing","Missing evidence",IF(T19>365,"Stale assessment",IF(COUNTIFS($B$2:$B$264,B19,$G$2:$G$264,G19)>1,"Duplicate competency record",IF(INDEX(employees!$H$2:$H$37,MATCH(B19,employees!$A$2:$A$37,0))="Inactive","Inactive account","OK")))) -> Missing evidence
A20: A0019 | B20: E003 | C20: =IFERROR(INDEX(employees!$B$2:$B$37,MATCH(B20,employees!$A$2:$A$37,0)),"") -> Jamie Taylor | D20: =IFERROR(INDEX(employees!$C$2:$C$37,MATCH(B20,employees!$A$2:$A$37,0)),"") -> Asset Management | E20: =IFERROR(INDEX(employees!$D$2:$D$37,MATCH(B20,employees!$A$2:$A$37,0)),"") -> Systems Engineering | F20: =IFERROR(INDEX(employees!$E$2:$E$37,MATCH(B20,employees!$A$2:$A$37,0)),"") -> Engineer | G20: C014 | H20: =IFERROR(INDEX(competency_model!$C$2:$C$25,MATCH(G20,competency_model!$A$2:$A$25,0)),"") -> Stakeholder Communication | I20: =IFERROR(INDEX(competency_model!$D$2:$D$25,MATCH(G20,competency_model!$A$2:$A$25,0)),"") -> Cross-Functional Updates | J20: =IFERROR(INDEX(competency_model!$F$2:$F$25,MATCH(G20,competency_model!$A$2:$A$25,0)),"") -> 3 | K20: =IFERROR(INDEX(competency_model!$G$2:$G$25,MATCH(G20,competency_model!$A$2:$A$25,0)),"") -> Medium | L20: 1 | M20: =MAX(0,J20-L20) -> 2 | N20: =IF(M20=0,"No Gap",IF(M20=1,"Minor",IF(M20=2,"Moderate","Critical"))) -> Moderate | O20: =IF(K20="High",3,IF(K20="Medium",2,1)) -> 2 | P20: =M20*O20 -> 4 | Q20: =IF(L20>=J20,"Ready","Development Needed") -> Development Needed | R20: Missing | S20: 46036.758 | T20: =TODAY()-S20 -> 165.24207 | U20: Manager | W20: =IF(R20="Missing","Missing evidence",IF(T20>365,"Stale assessment",IF(COUNTIFS($B$2:$B$264,B20,$G$2:$G$264,G20)>1,"Duplicate competency record",IF(INDEX(employees!$H$2:$H$37,MATCH(B20,employees!$A$2:$A$37,0))="Inactive","Inactive account","OK")))) -> Missing evidence
A21: A0020 | B21: E003 | C21: =IFERROR(INDEX(employees!$B$2:$B$37,MATCH(B21,employees!$A$2:$A$37,0)),"") -> Jamie Taylor | D21: =IFERROR(INDEX(employees!$C$2:$C$37,MATCH(B21,employees!$A$2:$A$37,0)),"") -> Asset Management | E21: =IFERROR(INDEX(employees!$D$2:$D$37,MATCH(B21,employees!$A$2:$A$37,0)),"") -> Systems Engineering | F21: =IFERROR(INDEX(employees!$E$2:$E$37,MATCH(B21,employees!$A$2:$A$37,0)),"") -> Engineer | G21: C024 | H21: =IFERROR(INDEX(competency_model!$C$2:$C$25,MATCH(G21,competency_model!$A$2:$A$25,0)),"") -> Asset Management | I21: =IFERROR(INDEX(competency_model!$D$2:$D$25,MATCH(G21,competency_model!$A$2:$A$25,0)),"") -> Engineering Performance Indicators | J21: =IFERROR(INDEX(competency_model!$F$2:$F$25,MATCH(G21,competency_model!$A$2:$A$25,0)),"") -> 3 | K21: =IFERROR(INDEX(competency_model!$G$2:$G$25,MATCH(G21,competency_model!$A$2:$A$25,0)),"") -> High | L21: 1 | M21: =MAX(0,J21-L21) -> 2 | N21: =IF(M21=0,"No Gap",IF(M21=1,"Minor",IF(M21=2,"Moderate","Critical"))) -> Moderate | O21: =IF(K21="High",3,IF(K21="Medium",2,1)) -> 3 | P21: =M21*O21 -> 6 | Q21: =IF(L21>=J21,"Ready","Development Needed") -> Development Needed | R21: Verified | S21: 46064.115 | T21: =TODAY()-S21 -> 137.88545 | U21: Manager | V21: Needs practical project evidence | W21: =IF(R21="Missing","Missing evidence",IF(T21>365,"Stale assessment",IF(COUNTIFS($B$2:$B$264,B21,$G$2:$G$264,G21)>1,"Duplicate competency record",IF(INDEX(employees!$H$2:$H$37,MATCH(B21,employees!$A$2:$A$37,0))="Inactive","Inactive account","OK")))) -> OK
A22: A0021 | B22: E003 | C22: =IFERROR(INDEX(employees!$B$2:$B$37,MATCH(B22,employees!$A$2:$A$37,0)),"") -> Jamie Taylor | D22: =IFERROR(INDEX(employees!$C$2:$C$37,MATCH(B22,employees!$A$2:$A$37,0)),"") -> Asset Management | E22: =IFERROR(INDEX(employees!$D$2:$D$37,MATCH(B22,employees!$A$2:$A$37,0)),"") -> Systems Engineering | F22: =IFERROR(INDEX(employees!$E$2:$E$37,MATCH(B22,employees!$A$2:$A$37,0)),"") -> Engineer | G22: C020 | H22: =IFERROR(INDEX(competency_model!$C$2:$C$25,MATCH(G22,competency_model!$A$2:$A$25,0)),"") -> User Support | I22: =IFERROR(INDEX(competency_model!$D$2:$D$25,MATCH(G22,competency_model!$A$2:$A$25,0)),"") -> Competency Tool User Support | J22: =IFERROR(INDEX(competency_model!$F$2:$F$25,MATCH(G22,competency_model!$A$2:$A$25,0)),"") -> 3 | K22: =IFERROR(INDEX(competency_model!$G$2:$G$25,MATCH(G22,competency_model!$A$2:$A$25,0)),"") -> Medium | L22: 1 | M22: =MAX(0,J22-L22) -> 2 | N22: =IF(M22=0,"No Gap",IF(M22=1,"Minor",IF(M22=2,"Moderate","Critical"))) -> Moderate | O22: =IF(K22="High",3,IF(K22="Medium",2,1)) -> 2 | P22: =M22*O22 -> 4 | Q22: =IF(L22>=J22,"Ready","Development Needed") -> Development Needed | R22: Verified | S22: 46050.805 | T22: =TODAY()-S22 -> 151.19505 | U22: Manager | W22: =IF(R22="Missing","Missing evidence",IF(T22>365,"Stale assessment",IF(COUNTIFS($B$2:$B$264,B22,$G$2:$G$264,G22)>1,"Duplicate competency record",IF(INDEX(employees!$H$2:$H$37,MATCH(B22,employees!$A$2:$A$37,0))="Inactive","Inactive account","OK")))) -> OK
A23: A0022 | B23: E003 | C23: =IFERROR(INDEX(employees!$B$2:$B$37,MATCH(B23,employees!$A$2:$A$37,0)),"") -> Jamie Taylor | D23: =IFERROR(INDEX(employees!$C$2:$C$37,MATCH(B23,employees!$A$2:$A$37,0)),"") -> Asset Management | E23: =IFERROR(INDEX(employees!$D$2:$D$37,MATCH(B23,employees!$A$2:$A$37,0)),"") -> Systems Engineering | F23: =IFERROR(INDEX(employees!$E$2:$E$37,MATCH(B23,employees!$A$2:$A$37,0)),"") -> Engineer | G23: C013 | H23: =IFERROR(INDEX(competency_model!$C$2:$C$25,MATCH(G23,competency_model!$A$2:$A$25,0)),"") -> Stakeholder Communication | I23: =IFERROR(INDEX(competency_model!$D$2:$D$25,MATCH(G23,competency_model!$A$2:$A$25,0)),"") -> Non-Technical Explanation | J23: =IFERROR(INDEX(competency_model!$F$2:$F$25,MATCH(G23,competency_model!$A$2:$A$25,0)),"") -> 3 | K23: =IFERROR(INDEX(competency_model!$G$2:$G$25,MATCH(G23,competency_model!$A$2:$A$25,0)),"") -> Medium | L23: 3 | M23: =MAX(0,J23-L23) -> 0 | N23: =IF(M23=0,"No Gap",IF(M23=1,"Minor",IF(M23=2,"Moderate","Critical"))) -> No Gap | O23: =IF(K23="High",3,IF(K23="Medium",2,1)) -> 2 | P23: =M23*O23 -> 0 | Q23: =IF(L23>=J23,"Ready","Development Needed") -> Ready | R23: Partial | S23: 46098.117 | T23: =TODAY()-S23 -> 103.8827 | U23: Self | V23: Ready for review | W23: =IF(R23="Missing","Missing evidence",IF(T23>365,"Stale assessment",IF(COUNTIFS($B$2:$B$264,B23,$G$2:$G$264,G23)>1,"Duplicate competency record",IF(INDEX(employees!$H$2:$H$37,MATCH(B23,employees!$A$2:$A$37,0))="Inactive","Inactive account","OK")))) -> OK
A24: A0023 | B24: E003 | C24: =IFERROR(INDEX(employees!$B$2:$B$37,MATCH(B24,employees!$A$2:$A$37,0)),"") -> Jamie Taylor | D24: =IFERROR(INDEX(employees!$C$2:$C$37,MATCH(B24,employees!$A$2:$A$37,0)),"") -> Asset Management | E24: =IFERROR(INDEX(employees!$D$2:$D$37,MATCH(B24,employees!$A$2:$A$37,0)),"") -> Systems Engineering | F24: =IFERROR(INDEX(employees!$E$2:$E$37,MATCH(B24,employees!$A$2:$A$37,0)),"") -> Engineer | G24: C006 | H24: =IFERROR(INDEX(competency_model!$C$2:$C$25,MATCH(G24,competency_model!$A$2:$A$25,0)),"") -> PowerPoint Presentation | I24: =IFERROR(INDEX(competency_model!$D$2:$D$25,MATCH(G24,competency_model!$A$2:$A$25,0)),"") -> Leadership Storytelling | J24: =IFERROR(INDEX(competency_model!$F$2:$F$25,MATCH(G24,competency_model!$A$2:$A$25,0)),"") -> 3 | K24: =IFERROR(INDEX(competency_model!$G$2:$G$25,MATCH(G24,competency_model!$A$2:$A$25,0)),"") -> Medium | L24: 2 | M24: =MAX(0,J24-L24) -> 1 | N24: =IF(M24=0,"No Gap",IF(M24=1,"Minor",IF(M24=2,"Moderate","Critical"))) -> Minor | O24: =IF(K24="High",3,IF(K24="Medium",2,1)) -> 2 | P24: =M24*O24 -> 2 | Q24: =IF(L24>=J24,"Ready","Development Needed") -> Development Needed | R24: Verified | S24: 45778.006 | T24: =TODAY()-S24 -> 423.99438 | U24: Manager | V24: Ready for review | W24: =IF(R24="Missing","Missing evidence",IF(T24>365,"Stale assessment",IF(COUNTIFS($B$2:$B$264,B24,$G$2:$G$264,G24)>1,"Duplicate competency record",IF(INDEX(employees!$H$2:$H$37,MATCH(B24,employees!$A$2:$A$37,0))="Inactive","Inactive account","OK")))) -> Stale assessment
A25: A0024 | B25: E004 | C25: =IFERROR(INDEX(employees!$B$2:$B$37,MATCH(B25,employees!$A$2:$A$37,0)),"") -> Riley Chen | D25: =IFERROR(INDEX(employees!$C$2:$C$37,MATCH(B25,employees!$A$2:$A$37,0)),"") -> Protection & Control | E25: =IFERROR(INDEX(employees!$D$2:$D$37,MATCH(B25,employees!$A$2:$A$37,0)),"") -> Engineering Management | F25: =IFERROR(INDEX(employees!$E$2:$E$37,MATCH(B25,employees!$A$2:$A$37,0)),"") -> Engineer | G25: C020 | H25: =IFERROR(INDEX(competency_model!$C$2:$C$25,MATCH(G25,competency_model!$A$2:$A$25,0)),"") -> User Support | I25: =IFERROR(INDEX(competency_model!$D$2:$D$25,MATCH(G25,competency_model!$A$2:$A$25,0)),"") -> Competency Tool User Support | J25: =IFERROR(INDEX(competency_model!$F$2:$F$25,MATCH(G25,competency_model!$A$2:$A$25,0)),"") -> 3 | K25: =IFERROR(INDEX(competency_model!$G$2:$G$25,MATCH(G25,competency_model!$A$2:$A$25,0)),"") -> Medium | L25: 1 | M25: =MAX(0,J25-L25) -> 2 | N25: =IF(M25=0,"No Gap",IF(M25=1,"Minor",IF(M25=2,"Moderate","Critical"))) -> Moderate | O25: =IF(K25="High",3,IF(K25="Medium",2,1)) -> 2 | P25: =M25*O25 -> 4 | Q25: =IF(L25>=J25,"Ready","Development Needed") -> Development Needed | R25: Verified | S25: 45676.128 | T25: =TODAY()-S25 -> 525.87174 | U25: Self | V25: Needs practical project evidence | W25: =IF(R25="Missing","Missing evidence",IF(T25>365,"Stale assessment",IF(COUNTIFS($B$2:$B$264,B25,$G$2:$G$264,G25)>1,"Duplicate competency record",IF(INDEX(employees!$H$2:$H$37,MATCH(B25,employees!$A$2:$A$37,0))="Inactive","Inactive account","OK")))) -> Stale assessment
A26: A0025 | B26: E004 | C26: =IFERROR(INDEX(employees!$B$2:$B$37,MATCH(B26,employees!$A$2:$A$37,0)),"") -> Riley Chen | D26: =IFERROR(INDEX(employees!$C$2:$C$37,MATCH(B26,employees!$A$2:$A$37,0)),"") -> Protection & Control | E26: =IFERROR(INDEX(employees!$D$2:$D$37,MATCH(B26,employees!$A$2:$A$37,0)),"") -> Engineering Management | F26: =IFERROR(INDEX(employees!$E$2:$E$37,MATCH(B26,employees!$A$2:$A$37,0)),"") -> Engineer | G26: C013 | H26: =IFERROR(INDEX(competency_model!$C$2:$C$25,MATCH(G26,competency_model!$A$2:$A$25,0)),"") -> Stakeholder Communication | I26: =IFERROR(INDEX(competency_model!$D$2:$D$25,MATCH(G26,competency_model!$A$2:$A$25,0)),"") -> Non-Technical Explanation | J26: =IFERROR(INDEX(competency_model!$F$2:$F$25,MATCH(G26,competency_model!$A$2:$A$25,0)),"") -> 3 | K26: =IFERROR(INDEX(competency_model!$G$2:$G$25,MATCH(G26,competency_model!$A$2:$A$25,0)),"") -> Medium | L26: 1 | M26: =MAX(0,J26-L26) -> 2 | N26: =IF(M26=0,"No Gap",IF(M26=1,"Minor",IF(M26=2,"Moderate","Critical"))) -> Moderate | O26: =IF(K26="High",3,IF(K26="Medium",2,1)) -> 2 | P26: =M26*O26 -> 4 | Q26: =IF(L26>=J26,"Ready","Development Needed") -> Development Needed | R26: Verified | S26: 45695.497 | T26: =TODAY()-S26 -> 506.5028 | U26: System | V26: Needs evidence upload | W26: =IF(R26="Missing","Missing evidence",IF(T26>365,"Stale assessment",IF(COUNTIFS($B$2:$B$264,B26,$G$2:$G$264,G26)>1,"Duplicate competency record",IF(INDEX(employees!$H$2:$H$37,MATCH(B26,employees!$A$2:$A$37,0))="Inactive","Inactive account","OK")))) -> Stale assessment
A27: A0026 | B27: E004 | C27: =IFERROR(INDEX(employees!$B$2:$B$37,MATCH(B27,employees!$A$2:$A$37,0)),"") -> Riley Chen | D27: =IFERROR(INDEX(employees!$C$2:$C$37,MATCH(B27,employees!$A$2:$A$37,0)),"") -> Protection & Control | E27: =IFERROR(INDEX(employees!$D$2:$D$37,MATCH(B27,employees!$A$2:$A$37,0)),"") -> Engineering Management | F27: =IFERROR(INDEX(employees!$E$2:$E$37,MATCH(B27,employees!$A$2:$A$37,0)),"") -> Engineer | G27: C004 | H27: =IFERROR(INDEX(competency_model!$C$2:$C$25,MATCH(G27,competency_model!$A$2:$A$25,0)),"") -> Excel Reporting | I27: =IFERROR(INDEX(competency_model!$D$2:$D$25,MATCH(G27,competency_model!$A$2:$A$25,0)),"") -> PivotTables and Power Query | J27: =IFERROR(INDEX(competency_model!$F$2:$F$25,MATCH(G27,competency_model!$A$2:$A$25,0)),"") -> 4 | K27: =IFERROR(INDEX(competency_model!$G$2:$G$25,MATCH(G27,competency_model!$A$2:$A$25,0)),"") -> High | L27: 4 | M27: =MAX(0,J27-L27) -> 0 | N27: =IF(M27=0,"No Gap",IF(M27=1,"Minor",IF(M27=2,"Moderate","Critical"))) -> No Gap | O27: =IF(K27="High",3,IF(K27="Medium",2,1)) -> 3 | P27: =M27*O27 -> 0 | Q27: =IF(L27>=J27,"Ready","Development Needed") -> Ready | R27: Verified | S27: 46088.63 | T27: =TODAY()-S27 -> 113.37041 | U27: System | V27: Ready for review | W27: =IF(R27="Missing","Missing evidence",IF(T27>365,"Stale assessment",IF(COUNTIFS($B$2:$B$264,B27,$G$2:$G$264,G27)>1,"Duplicate competency record",IF(INDEX(employees!$H$2:$H$37,MATCH(B27,employees!$A$2:$A$37,0))="Inactive","Inactive account","OK")))) -> OK
A28: A0027 | B28: E004 | C28: =IFERROR(INDEX(employees!$B$2:$B$37,MATCH(B28,employees!$A$2:$A$37,0)),"") -> Riley Chen | D28: =IFERROR(INDEX(employees!$C$2:$C$37,MATCH(B28,employees!$A$2:$A$37,0)),"") -> Protection & Control | E28: =IFERROR(INDEX(employees!$D$2:$D$37,MATCH(B28,employees!$A$2:$A$37,0)),"") -> Engineering Management | F28: =IFERROR(INDEX(employees!$E$2:$E$37,MATCH(B28,employees!$A$2:$A$37,0)),"") -> Engineer | G28: C014 | H28: =IFERROR(INDEX(competency_model!$C$2:$C$25,MATCH(G28,competency_model!$A$2:$A$25,0)),"") -> Stakeholder Communication | I28: =IFERROR(INDEX(competency_model!$D$2:$D$25,MATCH(G28,competency_model!$A$2:$A$25,0)),"") -> Cross-Functional Updates | J28: =IFERROR(INDEX(competency_model!$F$2:$F$25,MATCH(G28,competency_model!$A$2:$A$25,0)),"") -> 3 | K28: =IFERROR(INDEX(competency_model!$G$2:$G$25,MATCH(G28,competency_model!$A$2:$A$25,0)),"") -> Medium | L28: 1 | M28: =MAX(0,J28-L28) -> 2 | N28: =IF(M28=0,"No Gap",IF(M28=1,"Minor",IF(M28=2,"Moderate","Critical"))) -> Moderate | O28: =IF(K28="High",3,IF(K28="Medium",2,1)) -> 2 | P28: =M28*O28 -> 4 | Q28: =IF(L28>=J28,"Ready","Development Needed") -> Development Needed | R28: Verified | S28: 46079.027 | T28: =TODAY()-S28 -> 122.97259 | U28: Manager | V28: Discuss training route with leader | W28: =IF(R28="Missing","Missing evidence",IF(T28>365,"Stale assessment",IF(COUNTIFS($B$2:$B$264,B28,$G$2:$G$264,G28)>1,"Duplicate competency record",IF(INDEX(employees!$H$2:$H$37,MATCH(B28,employees!$A$2:$A$37,0))="Inactive","Inactive account","OK")))) -> OK
A29: A0028 | B29: E004 | C29: =IFERROR(INDEX(employees!$B$2:$B$37,MATCH(B29,employees!$A$2:$A$37,0)),"") -> Riley Chen | D29: =IFERROR(INDEX(employees!$C$2:$C$37,MATCH(B29,employees!$A$2:$A$37,0)),"") -> Protection & Control | E29: =IFERROR(INDEX(employees!$D$2:$D$37,MATCH(B29,employees!$A$2:$A$37,0)),"") -> Engineering Management | F29: =IFERROR(INDEX(employees!$E$2:$E$37,MATCH(B29,employees!$A$2:$A$37,0)),"") -> Engineer | G29: C007 | H29: =IFERROR(INDEX(competency_model!$C$2:$C$25,MATCH(G29,competency_model!$A$2:$A$25,0)),"") -> Engineering Documentation | I29: =IFERROR(INDEX(competency_model!$D$2:$D$25,MATCH(G29,competency_model!$A$2:$A$25,0)),"") -> Technical Documentation | J29: =IFERROR(INDEX(competency_model!$F$2:$F$25,MATCH(G29,competency_model!$A$2:$A$25,0)),"") -> 4 | K29: =IFERROR(INDEX(competency_model!$G$2:$G$25,MATCH(G29,competency_model!$A$2:$A$25,0)),"") -> High | L29: 1 | M29: =MAX(0,J29-L29) -> 3 | N29: =IF(M29=0,"No Gap",IF(M29=1,"Minor",IF(M29=2,"Moderate","Critical"))) -> Critical | O29: =IF(K29="High",3,IF(K29="Medium",2,1)) -> 3 | P29: =M29*O29 -> 9 | Q29: =IF(L29>=J29,"Ready","Development Needed") -> Development Needed | R29: Verified | S29: 46066.991 | T29: =TODAY()-S29 -> 135.00887 | U29: Manager | V29: Ready for review | W29: =IF(R29="Missing","Missing evidence",IF(T29>365,"Stale assessment",IF(COUNTIFS($B$2:$B$264,B29,$G$2:$G$264,G29)>1,"Duplicate competency record",IF(INDEX(employees!$H$2:$H$37,MATCH(B29,employees!$A$2:$A$37,0))="Inactive","Inactive account","OK")))) -> OK
A30: A0029 | B30: E004 | C30: =IFERROR(INDEX(employees!$B$2:$B$37,MATCH(B30,employees!$A$2:$A$37,0)),"") -> Riley Chen | D30: =IFERROR(INDEX(employees!$C$2:$C$37,MATCH(B30,employees!$A$2:$A$37,0)),"") -> Protection & Control | E30: =IFERROR(INDEX(employees!$D$2:$D$37,MATCH(B30,employees!$A$2:$A$37,0)),"") -> Engineering Management | F30: =IFERROR(INDEX(employees!$E$2:$E$37,MATCH(B30,employees!$A$2:$A$37,0)),"") -> Engineer | G30: C006 | H30: =IFERROR(INDEX(competency_model!$C$2:$C$25,MATCH(G30,competency_model!$A$2:$A$25,0)),"") -> PowerPoint Presentation | I30: =IFERROR(INDEX(competency_model!$D$2:$D$25,MATCH(G30,competency_model!$A$2:$A$25,0)),"") -> Leadership Storytelling | J30: =IFERROR(INDEX(competency_model!$F$2:$F$25,MATCH(G30,competency_model!$A$2:$A$25,0)),"") -> 3 | K30: =IFERROR(INDEX(competency_model!$G$2:$G$25,MATCH(G30,competency_model!$A$2:$A$25,0)),"") -> Medium | L30: 2 | M30: =MAX(0,J30-L30) -> 1 | N30: =IF(M30=0,"No Gap",IF(M30=1,"Minor",IF(M30=2,"Moderate","Critical"))) -> Minor | O30: =IF(K30="High",3,IF(K30="Medium",2,1)) -> 2 | P30: =M30*O30 -> 2 | Q30: =IF(L30>=J30,"Ready","Development Needed") -> Development Needed | R30: Partial | S30: 46101.762 | T30: =TODAY()-S30 -> 100.23822 | U30: Self | V30: Needs practical project evidence | W30: =IF(R30="Missing","Missing evidence",IF(T30>365,"Stale assessment",IF(COUNTIFS($B$2:$B$264,B30,$G$2:$G$264,G30)>1,"Duplicate competency record",IF(INDEX(employees!$H$2:$H$37,MATCH(B30,employees!$A$2:$A$37,0))="Inactive","Inactive account","OK")))) -> Duplicate competency record
A31: A0030 | B31: E004 | C31: =IFERROR(INDEX(employees!$B$2:$B$37,MATCH(B31,employees!$A$2:$A$37,0)),"") -> Riley Chen | D31: =IFERROR(INDEX(employees!$C$2:$C$37,MATCH(B31,employees!$A$2:$A$37,0)),"") -> Protection & Control | E31: =IFERROR(INDEX(employees!$D$2:$D$37,MATCH(B31,employees!$A$2:$A$37,0)),"") -> Engineering Management | F31: =IFERROR(INDEX(employees!$E$2:$E$37,MATCH(B31,employees!$A$2:$A$37,0)),"") -> Engineer | G31: C023 | H31: =IFERROR(INDEX(competency_model!$C$2:$C$25,MATCH(G31,competency_model!$A$2:$A$25,0)),"") -> PowerPoint Presentation | I31: =IFERROR(INDEX(competency_model!$D$2:$D$25,MATCH(G31,competency_model!$A$2:$A$25,0)),"") -> Executive Summary Slides | J31: =IFERROR(INDEX(competency_model!$F$2:$F$25,MATCH(G31,competency_model!$A$2:$A$25,0)),"") -> 3 | K31: =IFERROR(INDEX(competency_model!$G$2:$G$25,MATCH(G31,competency_model!$A$2:$A$25,0)),"") -> Medium | L31: 2 | M31: =MAX(0,J31-L31) -> 1 | N31: =IF(M31=0,"No Gap",IF(M31=1,"Minor",IF(M31=2,"Moderate","Critical"))) -> Minor | O31: =IF(K31="High",3,IF(K31="Medium",2,1)) -> 2 | P31: =M31*O31 -> 2 | Q31: =IF(L31>=J31,"Ready","Development Needed") -> Development Needed | R31: Missing | S31: 45968.813 | T31: =TODAY()-S31 -> 233.1867 | U31: System | W31: =IF(R31="Missing","Missing evidence",IF(T31>365,"Stale assessment",IF(COUNTIFS($B$2:$B$264,B31,$G$2:$G$264,G31)>1,"Duplicate competency record",IF(INDEX(employees!$H$2:$H$37,MATCH(B31,employees!$A$2:$A$37,0))="Inactive","Inactive account","OK")))) -> Missing evidence
A32: A0031 | B32: E004 | C32: =IFERROR(INDEX(employees!$B$2:$B$37,MATCH(B32,employees!$A$2:$A$37,0)),"") -> Riley Chen | D32: =IFERROR(INDEX(employees!$C$2:$C$37,MATCH(B32,employees!$A$2:$A$37,0)),"") -> Protection & Control | E32: =IFERROR(INDEX(employees!$D$2:$D$37,MATCH(B32,employees!$A$2:$A$37,0)),"") -> Engineering Management | F32: =IFERROR(INDEX(employees!$E$2:$E$37,MATCH(B32,employees!$A$2:$A$37,0)),"") -> Engineer | G32: C019 | H32: =IFERROR(INDEX(competency_model!$C$2:$C$25,MATCH(G32,competency_model!$A$2:$A$25,0)),"") -> Competency Systems | I32: =IFERROR(INDEX(competency_model!$D$2:$D$25,MATCH(G32,competency_model!$A$2:$A$25,0)),"") -> Competency Model Maintenance | J32: =IFERROR(INDEX(competency_model!$F$2:$F$25,MATCH(G32,competency_model!$A$2:$A$25,0)),"") -> 3 | K32: =IFERROR(INDEX(competency_model!$G$2:$G$25,MATCH(G32,competency_model!$A$2:$A$25,0)),"") -> High | L32: 3 | M32: =MAX(0,J32-L32) -> 0 | N32: =IF(M32=0,"No Gap",IF(M32=1,"Minor",IF(M32=2,"Moderate","Critical"))) -> No Gap | O32: =IF(K32="High",3,IF(K32="Medium",2,1)) -> 3 | P32: =M32*O32 -> 0 | Q32: =IF(L32>=J32,"Ready","Development Needed") -> Ready | R32: Missing | S32: 45982.961 | T32: =TODAY()-S32 -> 219.0393 | U32: Manager | V32: Needs evidence upload | W32: =IF(R32="Missing","Missing evidence",IF(T32>365,"Stale assessment",IF(COUNTIFS($B$2:$B$264,B32,$G$2:$G$264,G32)>1,"Duplicate competency record",IF(INDEX(employees!$H$2:$H$37,MATCH(B32,employees!$A$2:$A$37,0))="Inactive","Inactive account","OK")))) -> Missing evidence
A33: A0032 | B33: E005 | C33: =IFERROR(INDEX(employees!$B$2:$B$37,MATCH(B33,employees!$A$2:$A$37,0)),"") -> Jamie Williams | D33: =IFERROR(INDEX(employees!$C$2:$C$37,MATCH(B33,employees!$A$2:$A$37,0)),"") -> Systems Engineering | E33: =IFERROR(INDEX(employees!$D$2:$D$37,MATCH(B33,employees!$A$2:$A$37,0)),"") -> Testing & Validation | F33: =IFERROR(INDEX(employees!$E$2:$E$37,MATCH(B33,employees!$A$2:$A$37,0)),"") -> Senior Engineer | G33: C018 | H33: =IFERROR(INDEX(competency_model!$C$2:$C$25,MATCH(G33,competency_model!$A$2:$A$25,0)),"") -> Data Quality | I33: =IFERROR(INDEX(competency_model!$D$2:$D$25,MATCH(G33,competency_model!$A$2:$A$25,0)),"") -> Assessment Evidence Validation | J33: =IFERROR(INDEX(competency_model!$F$2:$F$25,MATCH(G33,competency_model!$A$2:$A$25,0)),"") -> 4 | K33: =IFERROR(INDEX(competency_model!$G$2:$G$25,MATCH(G33,competency_model!$A$2:$A$25,0)),"") -> High | L33: 4 | M33: =MAX(0,J33-L33) -> 0 | N33: =IF(M33=0,"No Gap",IF(M33=1,"Minor",IF(M33=2,"Moderate","Critical"))) -> No Gap | O33: =IF(K33="High",3,IF(K33="Medium",2,1)) -> 3 | P33: =M33*O33 -> 0 | Q33: =IF(L33>=J33,"Ready","Development Needed") -> Ready | R33: Partial | S33: 46035.805 | T33: =TODAY()-S33 -> 166.19521 | U33: Manager | W33: =IF(R33="Missing","Missing evidence",IF(T33>365,"Stale assessment",IF(COUNTIFS($B$2:$B$264,B33,$G$2:$G$264,G33)>1,"Duplicate competency record",IF(INDEX(employees!$H$2:$H$37,MATCH(B33,employees!$A$2:$A$37,0))="Inactive","Inactive account","OK")))) -> OK
A34: A0033 | B34: E005 | C34: =IFERROR(INDEX(employees!$B$2:$B$37,MATCH(B34,employees!$A$2:$A$37,0)),"") -> Jamie Williams | D34: =IFERROR(INDEX(employees!$C$2:$C$37,MATCH(B34,employees!$A$2:$A$37,0)),"") -> Systems Engineering | E34: =IFERROR(INDEX(employees!$D$2:$D$37,MATCH(B34,employees!$A$2:$A$37,0)),"") -> Testing & Validation | F34: =IFERROR(INDEX(employees!$E$2:$E$37,MATCH(B34,employees!$A$2:$A$37,0)),"") -> Senior Engineer | G34: C012 | H34: =IFERROR(INDEX(competency_model!$C$2:$C$25,MATCH(G34,competency_model!$A$2:$A$25,0)),"") -> Safety / Compliance | I34: =IFERROR(INDEX(competency_model!$D$2:$D$25,MATCH(G34,competency_model!$A$2:$A$25,0)),"") -> Engineering Safety Awareness | J34: =IFERROR(INDEX(competency_model!$F$2:$F$25,MATCH(G34,competency_model!$A$2:$A$25,0)),"") -> 4 | K34: =IFERROR(INDEX(competency_model!$G$2:$G$25,MATCH(G34,competency_model!$A$2:$A$25,0)),"") -> High | L34: 2 | M34: =MAX(0,J34-L34) -> 2 | N34: =IF(M34=0,"No Gap",IF(M34=1,"Minor",IF(M34=2,"Moderate","Critical"))) -> Moderate | O34: =IF(K34="High",3,IF(K34="Medium",2,1)) -> 3 | P34: =M34*O34 -> 6 | Q34: =IF(L34>=J34,"Ready","Development Needed") -> Development Needed | R34: Verified | S34: 46097.815 | T34: =TODAY()-S34 -> 104.18508 | U34: System | V34: Needs practical project evidence | W34: =IF(R34="Missing","Missing evidence",IF(T34>365,"Stale assessment",IF(COUNTIFS($B$2:$B$264,B34,$G$2:$G$264,G34)>1,"Duplicate competency record",IF(INDEX(employees!$H$2:$H$37,MATCH(B34,employees!$A$2:$A$37,0))="Inactive","Inactive account","OK")))) -> OK
A35: A0034 | B35: E005 | C35: =IFERROR(INDEX(employees!$B$2:$B$37,MATCH(B35,employees!$A$2:$A$37,0)),"") -> Jamie Williams | D35: =IFERROR(INDEX(employees!$C$2:$C$37,MATCH(B35,employees!$A$2:$A$37,0)),"") -> Systems Engineering | E35: =IFERROR(INDEX(employees!$D$2:$D$37,MATCH(B35,employees!$A$2:$A$37,0)),"") -> Testing & Validation | F35: =IFERROR(INDEX(employees!$E$2:$E$37,MATCH(B35,employees!$A$2:$A$37,0)),"") -> Senior Engineer | G35: C004 | H35: =IFERROR(INDEX(competency_model!$C$2:$C$25,MATCH(G35,competency_model!$A$2:$A$25,0)),"") -> Excel Reporting | I35: =IFERROR(INDEX(competency_model!$D$2:$D$25,MATCH(G35,competency_model!$A$2:$A$25,0)),"") -> PivotTables and Power Query | J35: =IFERROR(INDEX(competency_model!$F$2:$F$25,MATCH(G35,competency_model!$A$2:$A$25,0)),"") -> 4 | K35: =IFERROR(INDEX(competency_model!$G$2:$G$25,MATCH(G35,competency_model!$A$2:$A$25,0)),"") -> High | L35: 1 | M35: =MAX(0,J35-L35) -> 3 | N35: =IF(M35=0,"No Gap",IF(M35=1,"Minor",IF(M35=2,"Moderate","Critical"))) -> Critical | O35: =IF(K35="High",3,IF(K35="Medium",2,1)) -> 3 | P35: =M35*O35 -> 9 | Q35: =IF(L35>=J35,"Ready","Development Needed") -> Development Needed | R35: Verified | S35: 46114.539 | T35: =TODAY()-S35 -> 87.461069 | U35: System | V35: Needs evidence upload | W35: =IF(R35="Missing","Missing evidence",IF(T35>365,"Stale assessment",IF(COUNTIFS($B$2:$B$264,B35,$G$2:$G$264,G35)>1,"Duplicate competency record",IF(INDEX(employees!$H$2:$H$37,MATCH(B35,employees!$A$2:$A$37,0))="Inactive","Inactive account","OK")))) -> OK
A36: A0035 | B36: E005 | C36: =IFERROR(INDEX(employees!$B$2:$B$37,MATCH(B36,employees!$A$2:$A$37,0)),"") -> Jamie Williams | D36: =IFERROR(INDEX(employees!$C$2:$C$37,MATCH(B36,employees!$A$2:$A$37,0)),"") -> Systems Engineering | E36: =IFERROR(INDEX(employees!$D$2:$D$37,MATCH(B36,employees!$A$2:$A$37,0)),"") -> Testing & Validation | F36: =IFERROR(INDEX(employees!$E$2:$E$37,MATCH(B36,employees!$A$2:$A$37,0)),"") -> Senior Engineer | G36: C017 | H36: =IFERROR(INDEX(competency_model!$C$2:$C$25,MATCH(G36,competency_model!$A$2:$A$25,0)),"") -> Data Quality | I36: =IFERROR(INDEX(competency_model!$D$2:$D$25,MATCH(G36,competency_model!$A$2:$A$25,0)),"") -> Duplicate and Missing Value Checks | J36: =IFERROR(INDEX(competency_model!$F$2:$F$25,MATCH(G36,competency_model!$A$2:$A$25,0)),"") -> 4 | K36: =IFERROR(INDEX(competency_model!$G$2:$G$25,MATCH(G36,competency_model!$A$2:$A$25,0)),"") -> High | L36: 4 | M36: =MAX(0,J36-L36) -> 0 | N36: =IF(M36=0,"No Gap",IF(M36=1,"Minor",IF(M36=2,"Moderate","Critical"))) -> No Gap | O36: =IF(K36="High",3,IF(K36="Medium",2,1)) -> 3 | P36: =M36*O36 -> 0 | Q36: =IF(L36>=J36,"Ready","Development Needed") -> Ready | R36: Verified | S36: 46017.392 | T36: =TODAY()-S36 -> 184.60828 | U36: Manager | V36: Needs evidence upload | W36: =IF(R36="Missing","Missing evidence",IF(T36>365,"Stale assessment",IF(COUNTIFS($B$2:$B$264,B36,$G$2:$G$264,G36)>1,"Duplicate competency record",IF(INDEX(employees!$H$2:$H$37,MATCH(B36,employees!$A$2:$A$37,0))="Inactive","Inactive account","OK")))) -> OK
